Workbook

Sheet 星级要求
A1: 星星 | B1: 0级解锁 | C1: 第 1 层 | D1: 第 2 层 | E1: 第 3 层 | F1: 第 4 层 | G1: 第 5 层 | H1: 第 6 层 | I1: 全部的
B2: 10* | C2: 1 | D2: 1 | E2: 2 | F2: 2 | G2: 2 | H2: 2 | I2: 20
A3: ⭐️ | C3: 5 | D3: 5 | E3: 5 | F3: 5 | G3: 5 | H3: 15 | I3: 40
A4: ⭐️⭐️ | B4: - | C4: 15 | D4: 15 | E4: 15 | F4: 15 | G4: 15 | H4: 40 | I4: 115
A5: ⭐️⭐️⭐️ | B5: - | C5: 40 | D5: 40 | E5: 40 | F5: 40 | G5: 40 | H5: 100 | I5: 300
A6: ⭐️⭐️⭐️⭐️ | B6: - | C6: 100 | D6: 100 | E6: 100 | F6: 100 | G6: 100 | H6: 100 | I6: 600
I7: =SUM(I2:I6) -> 1075
K8: =1911/I7 -> 1.7776744

Sheet 英雄升级要求
A1: 等级 | B1: 英雄经验值 | C1: 需要城镇中心 | D1: 部队容量 | E1: 伴游 | O1: 1500
A2: 1 | B2: 0 | C2: 4 | D2: 65 | E2: 2 | O2: =-1500 -> -1500
A3: 2 | B3: 480 | C3: 4 | D3: 140 | E3: 2
A4: 3 | B4: 690 | C4: 4 | D4: 220 | E4: 2
A5: 4 | B5: 920 | C5: 4 | D5: 305 | E5: 2
A6: 5 | B6: 1200 | C6: 4 | D6: 400 | E6: 3
A7: 6 | B7: 1500 | C7: 4 | D7: 500 | E7: 3
A8: 7 | B8: 1800 | C8: 4 | D8: 605 | E8: 3
A9: 8 | B9: 2200 | C9: 4 | D9: 720 | E9: 3
A10: 9 | B10: 2600 | C10: 4 | D10: 840 | E10: 3
A11: 10 | B11: 3100 | C11: 4 | D11: 970 | E11: 4
A12: 11 | B12: 3800 | C12: 4 | D12: 1100 | E12: 4
A13: 12 | B13: 4200 | C13: 4 | D13: 1240 | E13: 4
A14: 13 | B14: 5100 | C14: 4 | D14: 1390 | E14: 4
... A81: 80 | B81: 2400000 | C81: 30 | D81: 13470 | E81: 10

Sheet 星级加成数值
A1: SSR | B1: SR | C1: R
A2: （满级*2-满级）/30 | B2: （满级*1.7-满级）/30 | C2: （满级*1.5-满级）/30

Sheet 主角数值
A1: 等级 | B1: HP | C1: ATK | D1: CRIT% | E1: CRIT_DMG | F1: SPD | G1: 主角DEF | H1: 丧尸DEF | I1: DPS | J1: k常数
A2: 1 | B2: 2000 | C2: 320 | D2: 0.5 | E2: 1.5 | F2: 2 | G2: 100 | H2: 120 | I2: =C2*((1+D2*(E2-1)))*(1-(H2/(H2+$J$2)))*F2 -> 114.28571 | J2: 20
A3: 2 | B3: 2000 | C3: 400 | D3: 0.5 | E3: 1.5 | F3: 2 | G3: 100 | H3: 120 | I3: =C3*((1+D3*(E3-1)))*(1-(H3/(H3+$J$2)))*F3 -> 142.85714
A4: 3 | B4: 2000 | C4: 480 | D4: 0.5 | E4: 1.5 | F4: 2 | G4: 100 | H4: 120 | I4: =C4*((1+D4*(E4-1)))*(1-(H4/(H4+$J$2)))*F4 -> 171.42857
A5: 4 | B5: 2000 | C5: 560 | D5: 0.5 | E5: 1.5 | F5: 2 | G5: 100 | H5: 120 | I5: =C5*((1+D5*(E5-1)))*(1-(H5/(H5+$J$2)))*F5 -> 200
A6: 5 | B6: 2000 | C6: 640 | D6: 0.5 | E6: 1.5 | F6: 2 | G6: 100 | H6: 120 | I6: =C6*((1+D6*(E6-1)))*(1-(H6/(H6+$J$2)))*F6 -> 228.57143
A7: 6 | B7: 2000 | C7: 720 | D7: 0.5 | E7: 1.5 | F7: 2 | G7: 100 | H7: 120 | I7: =C7*((1+D7*(E7-1)))*(1-(H7/(H7+$J$2)))*F7 -> 257.14286
A8: 7 | B8: 2000 | C8: 800 | D8: 0.5 | E8: 1.5 | F8: 2 | G8: 100 | H8: 120 | I8: =C8*((1+D8*(E8-1)))*(1-(H8/(H8+$J$2)))*F8 -> 285.71429
A9: 8 | B9: 2000 | C9: 880 | D9: 0.5 | E9: 1.5 | F9: 2 | G9: 100 | H9: 120 | I9: =C9*((1+D9*(E9-1)))*(1-(H9/(H9+$J$2)))*F9 -> 314.28571
A10: 9 | B10: 2000 | C10: 960 | D10: 0.5 | E10: 1.5 | F10: 2 | G10: 100 | H10: 120 | I10: =C10*((1+D10*(E10-1)))*(1-(H10/(H10+$J$2)))*F10 -> 342.85714
A11: 10 | B11: 2000 | C11: 1040 | D11: 0.5 | E11: 1.5 | F11: 2 | G11: 100 | H11: 120 | I11: =C11*((1+D11*(E11-1)))*(1-(H11/(H11+$J$2)))*F11 -> 371.42857

Sheet 英雄数值
A1: 英雄ID | B1: 英雄名称 | C1: 品阶 | D1: 职业 | E1: Level | F1: ATK | G1: DEF | H1: HP | I1: CRIT% | J1: CRIT_DMG | K1: SPD | L1: power
A2: ID | B2: Name | C2: Rank | D2: Vocation | E2: Level | F2: Atk | G2: Def | H2: Hp | I2: Crit | J2: CritDamage | K2: Speed | L2: Power
A3: Key | B3: String | C3: String | D3: String | E3: Int | F3: Int | G3: Int | H3: Int | I3: Float | J3: Int | K3: Int | L3: Float
A4: 1 | B4: Isabella Frost | C4: SSR | D4: SNIP | E4: 1 | F4: =[1]标准人!B2*1.8 -> 180 | G4: =[1]标准人!C2*1.45 -> 725 | H4: =[1]标准人!D2*0.86 -> 1720 | I4: 0.4 | J4: 2 | K4: 1 | L4: =IF(D4="SNIP",((F4*0.4+G4*0.01+H4*1)*10.3),IF(D4="DPS",(F4*0.17+G4*0.05+H4*0.2)*30,(F4*0.1+G4*0.2+H4*1)*10/2.1)) -> 18532.275
A5: 1 | B5: Isabella Frost | C5: SSR | D5: SNIP | E5: 2 | F5: =[1]标准人!B3*1.8 -> 252 | G5: =[1]标准人!C3*1.45 -> 740.979 | H5: =[1]标准人!D3*0.86 -> 1892 | I5: 0.4 | J5: 2 | K5: 1 | L5: =IF(D5="SNIP",((F5*0.4+G5*0.01+H5*1)*10.3),IF(D5="DPS",(F5*0.17+G5*0.05+H5*0.2)*30,(F5*0.1+G5*0.2+H5*1)*10/2.1)) -> 20602.161
A6: 1 | B6: Isabella Frost | C6: SSR | D6: SNIP | E6: 3 | F6: =[1]标准人!B4*1.8 -> 324 | G6: =[1]标准人!C4*1.45 -> 756.958 | H6: =[1]标准人!D4*0.86 -> 2064 | I6: 0.4 | J6: 2 | K6: 1 | L6: =IF(D6="SNIP",((F6*0.4+G6*0.01+H6*1)*10.3),IF(D6="DPS",(F6*0.17+G6*0.05+H6*0.2)*30,(F6*0.1+G6*0.2+H6*1)*10/2.1)) -> 22672.047
A7: 1 | B7: Isabella Frost | C7: SSR | D7: SNIP | E7: 4 | F7: =[1]标准人!B5*1.8 -> 396 | G7: =[1]标准人!C5*1.45 -> 772.937 | H7: =[1]标准人!D5*0.86 -> 2236 | I7: 0.4 | J7: 2 | K7: 1 | L7: =IF(D7="SNIP",((F7*0.4+G7*0.01+H7*1)*10.3),IF(D7="DPS",(F7*0.17+G7*0.05+H7*0.2)*30,(F7*0.1+G7*0.2+H7*1)*10/2.1)) -> 24741.933
A8: 1 | B8: Isabella Frost | C8: SSR | D8: SNIP | E8: 5 | F8: =[1]标准人!B6*1.8 -> 468 | G8: =[1]标准人!C6*1.45 -> 788.916 | H8: =[1]标准人!D6*0.86 -> 2408 | I8: 0.4 | J8: 2 | K8: 1 | L8: =IF(D8="SNIP",((F8*0.4+G8*0.01+H8*1)*10.3),IF(D8="DPS",(F8*0.17+G8*0.05+H8*0.2)*30,(F8*0.1+G8*0.2+H8*1)*10/2.1)) -> 26811.818
A9: 1 | B9: Isabella Frost | C9: SSR | D9: SNIP | E9: 6 | F9: =[1]标准人!B7*1.8 -> 540 | G9: =[1]标准人!C7*1.45 -> 804.895 | H9: =[1]标准人!D7*0.86 -> 2580 | I9: 0.4 | J9: 2 | K9: 1 | L9: =IF(D9="SNIP",((F9*0.4+G9*0.01+H9*1)*10.3),IF(D9="DPS",(F9*0.17+G9*0.05+H9*0.2)*30,(F9*0.1+G9*0.2+H9*1)*10/2.1)) -> 28881.704
A10: 1 | B10: Isabella Frost | C10: SSR | D10: SNIP | E10: 7 | F10: =[1]标准人!B8*1.8 -> 612 | G10: =[1]标准人!C8*1.45 -> 820.874 | H10: =[1]标准人!D8*0.86 -> 2752 | I10: 0.4 | J10: 2 | K10: 1 | L10: =IF(D10="SNIP",((F10*0.4+G10*0.01+H10*1)*10.3),IF(D10="DPS",(F10*0.17+G10*0.05+H10*0.2)*30,(F10*0.1+G10*0.2+H10*1)*10/2.1)) -> 30951.59
A11: 1 | B11: Isabella Frost | C11: SSR | D11: SNIP | E11: 8 | F11: =[1]标准人!B9*1.8 -> 684 | G11: =[1]标准人!C9*1.45 -> 836.853 | H11: =[1]标准人!D9*0.86 -> 2924 | I11: 0.4 | J11: 2 | K11: 1 | L11: =IF(D11="SNIP",((F11*0.4+G11*0.01+H11*1)*10.3),IF(D11="DPS",(F11*0.17+G11*0.05+H11*0.2)*30,(F11*0.1+G11*0.2+H11*1)*10/2.1)) -> 33021.476
A12: 1 | B12: Isabella Frost | C12: SSR | D12: SNIP | E12: 9 | F12: =[1]标准人!B10*1.8 -> 756 | G12: =[1]标准人!C10*1.45 -> 852.832 | H12: =[1]标准人!D10*0.86 -> 3096 | I12: 0.4 | J12: 2 | K12: 1 | L12: =IF(D12="SNIP",((F12*0.4+G12*0.01+H12*1)*10.3),IF(D12="DPS",(F12*0.17+G12*0.05+H12*0.2)*30,(F12*0.1+G12*0.2+H12*1)*10/2.1)) -> 35091.362
A13: 1 | B13: Isabella Frost | C13: SSR | D13: SNIP | E13: 10 | F13: =[1]标准人!B11*1.8 -> 828 | G13: =[1]标准人!C11*1.45 -> 868.811 | H13: =[1]标准人!D11*0.86 -> 3268 | I13: 0.4 | J13: 2 | K13: 1 | L13: =IF(D13="SNIP",((F13*0.4+G13*0.01+H13*1)*10.3),IF(D13="DPS",(F13*0.17+G13*0.05+H13*0.2)*30,(F13*0.1+G13*0.2+H13*1)*10/2.1)) -> 37161.248
A14: 1 | B14: Isabella Frost | C14: SSR | D14: SNIP | E14: 11 | F14: =[1]标准人!B12*1.8 -> 900 | G14: =[1]标准人!C12*1.45 -> 884.79 | H14: =[1]标准人!D12*0.86 -> 3440 | I14: 0.4 | J14: 2 | K14: 1 | L14: =IF(D14="SNIP",((F14*0.4+G14*0.01+H14*1)*10.3),IF(D14="DPS",(F14*0.17+G14*0.05+H14*0.2)*30,(F14*0.1+G14*0.2+H14*1)*10/2.1)) -> 39231.133
A15: 1 | B15: Isabella Frost | C15: SSR | D15: SNIP | E15: 12 | F15: =[1]标准人!B13*1.8 -> 972 | G15: =[1]标准人!C13*1.45 -> 900.769 | H15: =[1]标准人!D13*0.86 -> 3612 | I15: 0.4 | J15: 2 | K15: 1 | L15: =IF(D15="SNIP",((F15*0.4+G15*0.01+H15*1)*10.3),IF(D15="DPS",(F15*0.17+G15*0.05+H15*0.2)*30,(F15*0.1+G15*0.2+H15*1)*10/2.1)) -> 41301.019
... A83: 1 | B83: Isabella Frost | C83: SSR | D83: SNIP | E83: 80 | F83: =[1]标准人!B81*1.8 -> 5868 | G83: =[1]标准人!C81*1.45 -> 1987.341 | H83: =[1]标准人!D81*0.86 -> 15308 | I83: 0.4 | J83: 2 | K83: 1 | L83: =IF(D83="SNIP",((F83*0.4+G83*0.01+H83*1)*10.3),IF(D83="DPS",(F83*0.17+G83*0.05+H83*0.2)*30,(F83*0.1+G83*0.2+H83*1)*10/2.1)) -> 182053.26
A84: 2 | B84: Anvil | C84: SSR | D84: TANK | E84: 1 | F84: =[1]标准人!B2*0.76 -> 76 | G84: =[1]标准人!C2*1.33 -> 665 | H84: =[1]标准人!D2*2 -> 4000 | I84: 0.4 | J84: 2 | K84: 1 | L84: =IF(D84="SNIP",((F84*0.4+G84*0.01+H84*1)*10.3),IF(D84="DPS",(F84*0.17+G84*0.05+H84*0.2)*30,(F84*0.1+G84*0.2+H84*1)*10/2.1)) -> 19717.143
A85: 2 | B85: Anvil | C85: SSR | D85: TANK | E85: 2 | F85: =[1]标准人!B3*0.76 -> 106.4 | G85: =[1]标准人!C3*1.33 -> 679.6566 | H85: =[1]标准人!D3*2 -> 4400 | I85: 0.4 | J85: 2 | K85: 1 | L85: =IF(D85="SNIP",((F85*0.4+G85*0.01+H85*1)*10.3),IF(D85="DPS",(F85*0.17+G85*0.05+H85*0.2)*30,(F85*0.1+G85*0.2+H85*1)*10/2.1)) -> 21650.34
A86: 2 | B86: Anvil | C86: SSR | D86: TANK | E86: 3 | F86: =[1]标准人!B4*0.76 -> 136.8 | G86: =[1]标准人!C4*1.33 -> 694.3132 | H86: =[1]标准人!D4*2 -> 4800 | I86: 0.4 | J86: 2 | K86: 1 | L86: =IF(D86="SNIP",((F86*0.4+G86*0.01+H86*1)*10.3),IF(D86="DPS",(F86*0.17+G86*0.05+H86*0.2)*30,(F86*0.1+G86*0.2+H86*1)*10/2.1)) -> 23583.536
A87: 2 | B87: Anvil | C87: SSR | D87: TANK | E87: 4 | F87: =[1]标准人!B5*0.76 -> 167.2 | G87: =[1]标准人!C5*1.33 -> 708.9698 | H87: =[1]标准人!D5*2 -> 5200 | I87: 0.4 | J87: 2 | K87: 1 | L87: =IF(D87="SNIP",((F87*0.4+G87*0.01+H87*1)*10.3),IF(D87="DPS",(F87*0.17+G87*0.05+H87*0.2)*30,(F87*0.1+G87*0.2+H87*1)*10/2.1)) -> 25516.733
A88: 2 | B88: Anvil | C88: SSR | D88: TANK | E88: 5 | F88: =[1]标准人!B6*0.76 -> 197.6 | G88: =[1]标准人!C6*1.33 -> 723.6264 | H88: =[1]标准人!D6*2 -> 5600 | I88: 0.4 | J88: 2 | K88: 1 | L88: =IF(D88="SNIP",((F88*0.4+G88*0.01+H88*1)*10.3),IF(D88="DPS",(F88*0.17+G88*0.05+H88*0.2)*30,(F88*0.1+G88*0.2+H88*1)*10/2.1)) -> 27449.93
A89: 2 | B89: Anvil | C89: SSR | D89: TANK | E89: 6 | F89: =[1]标准人!B7*0.76 -> 228 | G89: =[1]标准人!C7*1.33 -> 738.283 | H89: =[1]标准人!D7*2 -> 6000 | I89: 0.4 | J89: 2 | K89: 1 | L89: =IF(D89="SNIP",((F89*0.4+G89*0.01+H89*1)*10.3),IF(D89="DPS",(F89*0.17+G89*0.05+H89*0.2)*30,(F89*0.1+G89*0.2+H89*1)*10/2.1)) -> 29383.127
A90: 2 | B90: Anvil | C90: SSR | D90: TANK | E90: 7 | F90: =[1]标准人!B8*0.76 -> 258.4 | G90: =[1]标准人!C8*1.33 -> 752.9396 | H90: =[1]标准人!D8*2 -> 6400 | I90: 0.4 | J90: 2 | K90: 1 | L90: =IF(D90="SNIP",((F90*0.4+G90*0.01+H90*1)*10.3),IF(D90="DPS",(F90*0.17+G90*0.05+H90*0.2)*30,(F90*0.1+G90*0.2+H90*1)*10/2.1)) -> 31316.323
A91: 2 | B91: Anvil | C91: SSR | D91: TANK | E91: 8 | F91: =[1]标准人!B9*0.76 -> 288.8 | G91: =[1]标准人!C9*1.33 -> 767.5962 | H91: =[1]标准人!D9*2 -> 6800 | I91: 0.4 | J91: 2 | K91: 1 | L91: =IF(D91="SNIP",((F91*0.4+G91*0.01+H91*1)*10.3),IF(D91="DPS",(F91*0.17+G91*0.05+H91*0.2)*30,(F91*0.1+G91*0.2+H91*1)*10/2.1)) -> 33249.52
A92: 2 | B92: Anvil | C92: SSR | D92: TANK | E92: 9 | F92: =[1]标准人!B10*0.76 -> 319.2 | G92: =[1]标准人!C10*1.33 -> 782.2528 | H92: =[1]标准人!D10*2 -> 7200 | I92: 0.4 | J92: 2 | K92: 1 | L92: =IF(D92="SNIP",((F92*0.4+G92*0.01+H92*1)*10.3),IF(D92="DPS",(F92*0.17+G92*0.05+H92*0.2)*30,(F92*0.1+G92*0.2+H92*1)*10/2.1)) -> 35182.717
A93: 2 | B93: Anvil | C93: SSR | D93: TANK | E93: 10 | F93: =[1]标准人!B11*0.76 -> 349.6 | G93: =[1]标准人!C11*1.33 -> 796.9094 | H93: =[1]标准人!D11*2 -> 7600 | I93: 0.4 | J93: 2 | K93: 1 | L93: =IF(D93="SNIP",((F93*0.4+G93*0.01+H93*1)*10.3),IF(D93="DPS",(F93*0.17+G93*0.05+H93*0.2)*30,(F93*0.1+G93*0.2+H93*1)*10/2.1)) -> 37115.914
A94: 2 | B94: Anvil | C94: SSR | D94: TANK | E94: 11 | F94: =[1]标准人!B12*0.76 -> 380 | G94: =[1]标准人!C12*1.33 -> 811.566 | H94: =[1]标准人!D12*2 -> 8000 | I94: 0.4 | J94: 2 | K94: 1 | L94: =IF(D94="SNIP",((F94*0.4+G94*0.01+H94*1)*10.3),IF(D94="DPS",(F94*0.17+G94*0.05+H94*0.2)*30,(F94*0.1+G94*0.2+H94*1)*10/2.1)) -> 39049.11
A95: 2 | B95: Anvil | C95: SSR | D95: TANK | E95: 12 | F95: =[1]标准人!B13*0.76 -> 410.4 | G95: =[1]标准人!C13*1.33 -> 826.2226 | H95: =[1]标准人!D13*2 -> 8400 | I95: 0.4 | J95: 2 | K95: 1 | L95: =IF(D95="SNIP",((F95*0.4+G95*0.01+H95*1)*10.3),IF(D95="DPS",(F95*0.17+G95*0.05+H95*0.2)*30,(F95*0.1+G95*0.2+H95*1)*10/2.1)) -> 40982.307
... A163: 2 | B163: Anvil | C163: SSR | D163: TANK | E163: 80 | F163: =[1]标准人!B81*0.76 -> 2477.6 | G163: =[1]标准人!C81*1.33 -> 1822.8714 | H163: =[1]标准人!D81*2 -> 35600 | I163: 0.4 | J163: 2 | K163: 1 | L163: =IF(D163="SNIP",((F163*0.4+G163*0.01+H163*1)*10.3),IF(D163="DPS",(F163*0.17+G163*0.05+H163*0.2)*30,(F163*0.1+G163*0.2+H163*1)*10/2.1)) -> 172439.69
A164: 3 | B164: Lena Volt | C164: SR | D164: SNIP | E164: 1 | F164: =[1]标准人!B2*1.2 -> 120 | G164: =[1]标准人!C2*1.2 -> 600 | H164: =[1]标准人!D2*0.74 -> 1480 | I164: 0.4 | J164: 2 | K164: 1 | L164: =IF(D164="SNIP",((F164*0.4+G164*0.01+H164*1)*10.3),IF(D164="DPS",(F164*0.17+G164*0.05+H164*0.2)*30,(F164*0.1+G164*0.2+H164*1)*10/2.1)) -> 15800.2
A165: 3 | B165: Lena Volt | C165: SR | D165: SNIP | E165: 2 | F165: =[1]标准人!B3*1.2 -> 168 | G165: =[1]标准人!C3*1.2 -> 613.224 | H165: =[1]标准人!D3*0.74 -> 1628 | I165: 0.4 | J165: 2 | K165: 1 | L165: =IF(D165="SNIP",((F165*0.4+G165*0.01+H165*1)*10.3),IF(D165="DPS",(F165*0.17+G165*0.05+H165*0.2)*30,(F165*0.1+G165*0.2+H165*1)*10/2.1)) -> 17523.722
A166: 3 | B166: Lena Volt | C166: SR | D166: SNIP | E166: 3 | F166: =[1]标准人!B4*1.2 -> 216 | G166: =[1]标准人!C4*1.2 -> 626.448 | H166: =[1]标准人!D4*0.74 -> 1776 | I166: 0.4 | J166: 2 | K166: 1 | L166: =IF(D166="SNIP",((F166*0.4+G166*0.01+H166*1)*10.3),IF(D166="DPS",(F166*0.17+G166*0.05+H166*0.2)*30,(F166*0.1+G166*0.2+H166*1)*10/2.1)) -> 19247.244
A167: 3 | B167: Lena Volt | C167: SR | D167: SNIP | E167: 4 | F167: =[1]标准人!B5*1.2 -> 264 | G167: =[1]标准人!C5*1.2 -> 639.672 | H167: =[1]标准人!D5*0.74 -> 1924 | I167: 0.4 | J167: 2 | K167: 1 | L167: =IF(D167="SNIP",((F167*0.4+G167*0.01+H167*1)*10.3),IF(D167="DPS",(F167*0.17+G167*0.05+H167*0.2)*30,(F167*0.1+G167*0.2+H167*1)*10/2.1)) -> 20970.766
A168: 3 | B168: Lena Volt | C168: SR | D168: SNIP | E168: 5 | F168: =[1]标准人!B6*1.2 -> 312 | G168: =[1]标准人!C6*1.2 -> 652.896 | H168: =[1]标准人!D6*0.74 -> 2072 | I168: 0.4 | J168: 2 | K168: 1 | L168: =IF(D168="SNIP",((F168*0.4+G168*0.01+H168*1)*10.3),IF(D168="DPS",(F168*0.17+G168*0.05+H168*0.2)*30,(F168*0.1+G168*0.2+H168*1)*10/2.1)) -> 22694.288
A169: 3 | B169: Lena Volt | C169: SR | D169: SNIP | E169: 6 | F169: =[1]标准人!B7*1.2 -> 360 | G169: =[1]标准人!C7*1.2 -> 666.12 | H169: =[1]标准人!D7*0.74 -> 2220 | I169: 0.4 | J169: 2 | K169: 1 | L169: =IF(D169="SNIP",((F169*0.4+G169*0.01+H169*1)*10.3),IF(D169="DPS",(F169*0.17+G169*0.05+H169*0.2)*30,(F169*0.1+G169*0.2+H169*1)*10/2.1)) -> 24417.81
A170: 3 | B170: Lena Volt | C170: SR | D170: SNIP | E170: 7 | F170: =[1]标准人!B8*1.2 -> 408 | G170: =[1]标准人!C8*1.2 -> 679.344 | H170: =[1]标准人!D8*0.74 -> 2368 | I170: 0.4 | J170: 2 | K170: 1 | L170: =IF(D170="SNIP",((F170*0.4+G170*0.01+H170*1)*10.3),IF(D170="DPS",(F170*0.17+G170*0.05+H170*0.2)*30,(F170*0.1+G170*0.2+H170*1)*10/2.1)) -> 26141.332
A171: 3 | B171: Lena Volt | C171: SR | D171: SNIP | E171: 8 | F171: =[1]标准人!B9*1.2 -> 456 | G171: =[1]标准人!C9*1.2 -> 692.568 | H171: =[1]标准人!D9*0.74 -> 2516 | I171: 0.4 | J171: 2 | K171: 1 | L171: =IF(D171="SNIP",((F171*0.4+G171*0.01+H171*1)*10.3),IF(D171="DPS",(F171*0.17+G171*0.05+H171*0.2)*30,(F171*0.1+G171*0.2+H171*1)*10/2.1)) -> 27864.855
A172: 3 | B172: Lena Volt | C172: SR | D172: SNIP | E172: 9 | F172: =[1]标准人!B10*1.2 -> 504 | G172: =[1]标准人!C10*1.2 -> 705.792 | H172: =[1]标准人!D10*0.74 -> 2664 | I172: 0.4 | J172: 2 | K172: 1 | L172: =IF(D172="SNIP",((F172*0.4+G172*0.01+H172*1)*10.3),IF(D172="DPS",(F172*0.17+G172*0.05+H172*0.2)*30,(F172*0.1+G172*0.2+H172*1)*10/2.1)) -> 29588.377
A173: 3 | B173: Lena Volt | C173: SR | D173: SNIP | E173: 10 | F173: =[1]标准人!B11*1.2 -> 552 | G173: =[1]标准人!C11*1.2 -> 719.016 | H173: =[1]标准人!D11*0.74 -> 2812 | I173: 0.4 | J173: 2 | K173: 1 | L173: =IF(D173="SNIP",((F173*0.4+G173*0.01+H173*1)*10.3),IF(D173="DPS",(F173*0.17+G173*0.05+H173*0.2)*30,(F173*0.1+G173*0.2+H173*1)*10/2.1)) -> 31311.899
A174: 3 | B174: Lena Volt | C174: SR | D174: SNIP | E174: 11 | F174: =[1]标准人!B12*1.2 -> 600 | G174: =[1]标准人!C12*1.2 -> 732.24 | H174: =[1]标准人!D12*0.74 -> 2960 | I174: 0.4 | J174: 2 | K174: 1 | L174: =IF(D174="SNIP",((F174*0.4+G174*0.01+H174*1)*10.3),IF(D174="DPS",(F174*0.17+G174*0.05+H174*0.2)*30,(F174*0.1+G174*0.2+H174*1)*10/2.1)) -> 33035.421
...

Sheet 英雄技能数值及描述
A1: 名称 | B1: 技能名称 | C1: 技能名称翻译 | D1: 等级要求 | E1: 技能描述 | F1: 技能描述翻译 | G1: 特效名称 | H1: 技能CD | I1: 技能类型 | J1: Level1 | K1: Level2 | L1: Level3 | M1: Level4 | N1: Level5 | O1: BUFF类技能参数 | P1: 控制类技能参数 | Q1: 特殊参数 | S1: 技能类型 | T1: 代号 | V1: 特效列表 | W1: 代号
A2: Isabella Frost | B2: 永夜终焉 | C2: Eternal Nightfall | D2: 1 | E2: 锁定全场生命值最低的3个敌人，依次发射贯穿冰弹，造成敌方生命上限$的真实伤害（无视防御）并有70%概率冻结目标2秒。 | F2: Locks on to the 3 enemies with the lowest HP, firing piercing ice bullets in sequence, dealing $% of max HP as true damage (ignores defense) with a 70% chance to freeze targets for 2 seconds. | G2: PE_MagicFieldBlue (UnityEngine.GameObject) | H2: 10 | I2: 1,2 | J2: 0.2 | K2: 0.23 | L2: 0.26 | M2: 0.29 | N2: 0.32 | P2: [0.7,2] | S2: 伤害类技能 | T2: 1 | V2: 眩晕
A3: Isabella Frost | B3: 寒冰血脉 | C3: Frostblood Lineage | D3: 1 | E3: 普通攻击有20%概率减速敌人5秒，并对已被冻结的敌人造成额外$伤害。 | F3: Basic attacks have a 20% chance to slow enemies for 5 seconds and deal an additional $ damage to frozen enemies. | H3: 0 | I3: 1,2 | J3: 0.2 | K3: 0.23 | L3: 0.26 | M3: 0.29 | N3: 0.32 | P3: [0.2,5] | S3: 控制类技能 | T3: 2 | V3: 冰冻 | W3: PE_MagicFieldBlue (UnityEngine.GameObject)
A4: Isabella Frost | B4: 集团继承者 | C4: Corporate Heir | D4: 1 | E4: 在基地中时，所有资源产量提升$。 | F4: While in the base, all resource production increases by $%. | H4: 0 | I4: 4 | J4: 0.06 | K4: 0.07 | L4: 0.08 | M4: 0.09 | N4: 0.1 | S4: BUFF类技能 | T4: 3 | V4: 嘲讽 | W4: PE_MagicEnchantBlue (UnityEngine.GameObject)
A5: Anvil | B5: 毁灭重铸 | C5: Ruinous Rebirth | D5: 1 | E5: 牺牲当前30%生命值，对周围所有敌人造成基于自身已损失生命值的$的伤害，并强制嘲讽所有敌人5秒 | F5: Sacrifices 30% of current HP to deal $% damage to all nearby enemies based on lost HP and force taunt all enemies for 5 seconds. | G5: PE_MagicEnchantBlue (UnityEngine.GameObject) | H5: 10 | I5: 1,2 | J5: 1 | K5: 1.2 | L5: 1.4 | M5: 1.6 | N5: 1.8 | P5: [1,5] | Q5: 0.3 | S5: 其他类技能 | T5: 4 | V5: 麻痹
A6: Anvil | B6: 纳米吞噬 | C6: Nanophage | D6: 1 | E6: 每次受到伤害，都会永久增加$最大生命值（有上限50%）。击败敌人时，回复自身最大生命值20%的血量 | F6: Each time damage is taken, permanently increases max HP by $% (capped at 50%). Defeating enemies restores 20% of max HP. | H6: 0 | I6: 3,3 | J6: 0.01 | K6: 0.02 | L6: 0.03 | M6: 0.04 | N6: 0.05 | O6: [0.2] | Q6: 0.5 | V6: 护盾
A7: Anvil | B7: 不屈意志 | C7: Indomitable Will | D7: 1 | E7: 首次阵亡时，会立即复活并恢复40%最大生命值，并在接下来10秒内攻击力提升$。 | F7: On first death, instantly revives with 40% max HP and increases attack by $% for 10 seconds. | G7: PE_MagicCircleBlue (UnityEngine.GameObject) | H7: 0 | I7: 3,3 | J7: 0.6 | K7: 0.65 | L7: 0.7 | M7: 0.75 | N7: 0.8 | O7: [0.4]
A8: Lena Volt | B8: 超载穿透弹 | C8: Overloaded Penetrator | D8: 1 | E8: 发射一枚穿透性子弹，对一条直线上的所有敌人造成高额伤害（对首个目标伤害最高,后续只有40%），并有30%使目标麻痹（无法行动）1.5秒。 | F8: Fires a piercing bullet that deals high damage to all enemies in a line (highest on first target, 40% on others), with a 30% chance to paralyze targets for 1.5 seconds. | G8: PE_LightningStrikeTall (UnityEngine.GameObject) | H8: 10 | I8: 1,2 | J8: 400 | K8: 450 | L8: 500 | M8: 550 | N8: 600 | O8: [0.3,1.5] | Q8: 0.4
A9: Lena Volt | B9: 弱点解析 | C9: Weakness Analysis | D9: 1 | E9: 普通攻击有$的概率造成无视部分防御的暴击。 | F9: Basic attacks have a $% chance to crit, ignoring part of the target’s defense. | H9: 0 | I9: 3 | J9: 0.1 | K9: 0.13 | L9: 0.16 | M9: 0.19 | N9: 0.22
A10: Lena Volt | B10: 应急供电 | C10: Emergency Power | D10: 1 | E10: 在基地中时，提升$石头生产效率。 | F10: While in the base, stone production efficiency increases by $%. | H10: 0 | I10: 4 | J10: 0.01 | K10: 0.02 | L10: 0.03 | M10: 0.04 | N10: 0.05
A11: Marcus Reed | B11: 碎颅猛击 | C11: Skullcrusher Strike | D11: 1 | E11: 冲向生命值最高的敌方目标，对其造成高额伤害并降低其20%护甲，持续5秒。 | F11: Charges at the enemy with the highest HP, dealing high damage and reducing their armor by 20% for 5 seconds. | H11: 10 | I11: 1,3 | J11: 300 | K11: 350 | L11: 400 | M11: 450 | N11: 500 | O11: [0.2,5]
A12: Marcus Reed | B12: 乘胜追击 | C12: Press the Advantage | D12: 1 | E12: 对生命值低于30%的敌人造成的伤害提升$。 | F12: Damage dealt to enemies below 30% HP increases by $%. | H12: 0 | I12: 2 | J12: 0.2 | K12: 0.22 | L12: 0.24 | M12: 0.26 | N12: 0.28 | Q12: 0.3
A13: Marcus Reed | B13: 极地生存 | C13: Arctic Survival | D13: 1 | E13: 在副玩法中，载具血量提升5%。 | F13: In side modes, vehicle HP increases by 5%. | H13: 0 | I13: 4 | O13: [0.05]
A14: Old Jack | B14: 举盾防御 | C14: Shield Wall | D14: 1 | E14: 为自身施加一个持续4秒的护盾，吸收$伤害 | F14: Gains a shield for 4 seconds that absorbs $ damage. | H14: 10 | I14: 3 | J14: 200 | K14: 300 | L14: 400 | M14: 500 | N14: 600 | Q14: 4
A15: Old Jack | B15: 战地经验 | C15: Battlefield Experience | D15: 1 | E15: 永久提升自身$的防御力 | F15: Permanently increases defense by $%. | H15: 0 | I15: 3 | J15: 200 | K15: 250 | L15: 300 | M15: 350 | N15: 400 | O15: En
A16: Old Jack | B16: 鼓舞 | C16: Rally | D16: 1 | E16: 提升周围友军$的攻击速度。 | F16: Increases nearby allies’ attack speed by $%. | H16: 0 | I16: 3 | J16: 0.05 | K16: 0.07 | L16: 0.09 | M16: 0.11 | N16: 0.13
A17: Jack(主角) | B17: 速攻 | C17: Blitz | D17: 5 | E17: 在5s内提高攻速百分之100 | F17: Increase attack speed by 100% within 5 seconds | H17: 20
A18: Jack（主角） | B18: 枪林弹雨 | C18: bullet rain | D18: 10 | E18: 切换成强力散弹枪，对前方扇形敌人造成攻击力60%的AOE伤害 | F18: Switch to a powerful shotgun and deal 60% AOE damage to the fan-shaped enemies ahead | H18: 初始值为（10s）之后便为20s
A19: Jack（主角） | B19: 强化攻速 | C19: Enhance Attack Speed | D19: 15 | E19: 基础攻速提高百分之50 | F19: Basic attack speed increased by 50% | H19: 0
A20: Jack（主角） | B20: 强壮体魄 | C20: Muscular Structure | D20: 20 | E20: 生命值提高百分之百 | F20: Increase health by 100% | H20: 0

Sheet 英雄技能数值及描述（副本）
A1: 名称 | B1: 技能名称 | C1: 技能描述 | D1: 技能CD | E1: 技能类型 | F1: 初始加成 | G1: 等级加成 | H1: Level2 | I1: Level3 | J1: Level4 | K1: Level5 | L1: BUFF类技能参数 | M1: 控制类技能参数 | N1: 特殊参数 | P1: 技能类型 | Q1: 代号
A2: ID | B2: Name | C2: Desc | D2: CD | E2: SkillType | F2: Primary | G2: Bonus
A3: Isabella Frost | B3: Eternal Nightfall | C3: Locks on to the 3 enemies with the lowest HP, firing piercing ice bullets in sequence, dealing $% of max HP as true damage (ignores defense) with a 70% chance to freeze targets for 2 seconds. | D3: 10 | E3: 1,2 | G3: [0.2,0.23,0.26,0.29,0.32] | H3: 0.23 | I3: 0.26 | J3: 0.29 | K3: 0.32 | M3: [0.7,2] | P3: 伤害类技能 | Q3: 1
A4: Isabella Frost | B4: Frostblood Lineage | C4: Basic attacks have a 20% chance to slow enemies for 5 seconds and deal an additional $ damage to frozen enemies. | D4: 0 | E4: 1,2 | G4: [0.2,0.23,0.26,0.29,0.33] | H4: 0.23 | I4: 0.26 | J4: 0.29 | K4: 0.32 | M4: [0.2,5] | P4: 控制类技能 | Q4: 2
A5: Isabella Frost | B5: Corporate Heir | C5: While in the base, all resource production increases by $%. | D5: 0 | E5: 4 | G5: [0.06,0.07,0.08,0.09,0.1] | H5: 0.07 | I5: 0.08 | J5: 0.09 | K5: 0.1 | P5: BUFF类技能 | Q5: 3
A6: Anvil | B6: Ruinous Rebirth | C6: Sacrifices 30% of current HP to deal $% damage to all nearby enemies based on lost HP and force taunt all enemies for 5 seconds. | D6: 10 | E6: 1,2 | G6: 1,1.2,1.4,1.6,1.8 | H6: 1.2 | I6: 1.4 | J6: 1.6 | K6: 1.8 | M6: [1,5] | N6: 0.3 | P6: 其他类技能 | Q6: 4
A7: Anvil | B7: Nanophage | C7: Each time damage is taken, permanently increases max HP by $% (capped at 50%). Defeating enemies restores 20% of max HP. | D7: 0 | E7: 3,3 | G7: 0.01 | H7: 0.02 | I7: 0.03 | J7: 0.04 | K7: 0.05 | L7: [0.2] | N7: 0.5
A8: Anvil | B8: Indomitable Will | C8: On first death, instantly revives with 40% max HP and increases attack by $% for 10 seconds. | D8: 0 | E8: 3,3 | G8: 0.6 | H8: 0.65 | I8: 0.7 | J8: 0.75 | K8: 0.8 | L8: [0.4]
A9: Lena Volt | B9: Overloaded Penetrator | C9: Fires a piercing bullet that deals high damage to all enemies in a line (highest on first target, 40% on others), with a 30% chance to paralyze targets for 1.5 seconds. | D9: 10 | E9: 1,2 | G9: 2000 | H9: 3000 | I9: 4000 | J9: 5000 | K9: 6000 | L9: [0.3,1.5] | N9: 0.4
A10: Lena Volt | B10: Weakness Analysis | C10: Basic attacks have a $% chance to crit, ignoring part of the target’s defense. | D10: 0 | E10: 3 | G10: 0.1 | H10: 0.13 | I10: 0.16 | J10: 0.19 | K10: 0.22
A11: Lena Volt | B11: Emergency Power | C11: While in the base, stone production efficiency increases by $%. | D11: 0 | E11: 4 | G11: 0.01 | H11: 0.02 | I11: 0.03 | J11: 0.04 | K11: 0.05
A12: Marcus Reed | B12: Skullcrusher Strike | C12: Charges at the enemy with the highest HP, dealing high damage and reducing their armor by 20% for 5 seconds. | D12: 10 | E12: 1,3 | G12: 1500 | H12: 2000 | I12: 2500 | J12: 3000 | K12: 3500 | L12: [0.2,5]
A13: Marcus Reed | B13: Press the Advantage | C13: Damage dealt to enemies below 30% HP increases by $%. | D13: 0 | E13: 2 | G13: 0.2 | H13: 0.22 | I13: 0.24 | J13: 0.26 | K13: 0.28 | N13: 0.3
A14: Marcus Reed | B14: Arctic Survival | C14: In side modes, vehicle HP increases by 5%. | D14: 0 | E14: 4 | L14: [0.05]
A15: Old Jack | B15: Shield Wall | C15: Gains a shield for 4 seconds that absorbs $ damage. | D15: 10 | E15: 3 | G15: 500 | H15: 1000 | I15: 1500 | J15: 2000 | K15: 2500 | N15: 4
A16: Old Jack | B16: Battlefield Experience | C16: Permanently increases defense by $%. | D16: 0 | E16: 3 | G16: 100 | H16: 150 | I16: 200 | J16: 250 | K16: 300
A17: Old Jack | B17: Rally | C17: Increases nearby allies’ attack speed by $%. | D17: 0 | E17: 3 | G17: 0.05 | H17: 0.07 | I17: 0.09 | J17: 0.11 | K17: 0.13

Sheet 英雄图鉴
A1: 英雄iD | B1: 英雄名称 | C1: 品阶 | D1: 英雄职业 | E1: 英雄称号 | F1: 英雄关键词 | G1: 英雄背景 | H1: 英雄台词 | I1: 英雄技能名称1 | J1: 英雄技能名称2 | K1: 英雄技能名称3 | L1: 英雄技能描述1 | M1: 英雄技能描述2 | N1: 英雄技能描述3
A2: ID | B2: HeroName | C2: Rarity | D2: HeroType | E2: HeroNickName | F2: HeroKeyword | G2: HeroBg | H2: HeroSay | I2: HeroSkill1 | J2: HeroSkill2 | K2: HeroSkill3 | L2: SkillDec1 | M2: SkillDec2 | N2: SkillDec3
A3: Key | B3: String | C3: String | D3: String | E3: String | F3: String | G3: String | H3: String | I3: String | J3: String | K3: String | L3: String | M3: String | N3: String
A4: 1 | B4: Isabella Frost | C4: SSR | D4: SNIP | E4: 永夜仲裁者 | F4: 全场狙击、冰冻控制、真实伤害 | G4: 永夜集团创始人的神秘女儿，C药物的首批完美适应者之一。她并未完全丧尸化，而是获得了操控寒冰并感知生命能量的能力。她认为自己是新世界的审判者，用冰冷的狙击枪执行她的“净化”。 | H4: 在永恒的寒冬中，接受你们的命运。 | I4: 永夜终焉 | J4: 寒冰血脉 | K4: 集团继承者 | L4: 锁定全场生命值最低的3个敌人，依次发射贯穿冰弹，造成巨额真实百分比伤害（无视防御）并有高概率冻结目标2秒。 | M4: 普通攻击有20%概率减速敌人，并对已被冻结的敌人造成额外伤害。 | N4: 在基地中时，所有资源产量中幅度提升。
A5: 2 | B5: Anvil | C5: SSR | D5: TANK | E5: 不灭巨人 | F5: 无限成长、狂暴复活、群体嘲讽 | G5: 一位在核爆中心奇迹生还的科学家，身体与实验中的纳米机器人融合。他不断吸收周围的金属与辐射来修复和强化自身，是一个近乎不死的存在 | H5: 疼痛……是我存在的证明！ | I5: 毁灭重铸 | J5: 纳米吞噬 | K5: 不屈意志 | L5: 牺牲当前30%生命值，对周围所有敌人造成基于自身已损失生命值的巨额伤害，并强制嘲讽所有敌人5秒。 | M5: 每次受到伤害，都会永久增加微量最大生命值（有上限）。击败敌人时，回复自身最大生命值一定百分比的血量。 | N5: 首次阵亡时，会立即复活并恢复40%最大生命值，并在接下来10秒内攻击力大幅提升。
A6: 3 | B6: Lena Volt | C6: SR | D6: SNIP | E6: 磁暴射手 | F6: 直线穿透、电磁麻痹、高暴击 | G6: 天才电工，自制了一把电磁狙击步枪。她的攻击能无视轻甲掩护，对关键目标造成致命打击。 | H6: 目标锁定，通道清空。 | I6: 超载穿透弹 | J6: 弱点解析 | K6: 应急供电 | L6: 发射一枚穿透性子弹，对一条直线上的所有敌人造成高额伤害（对首个目标伤害最高），并有概率使目标麻痹（无法行动）1.5秒。 | M6: 普通攻击有15%的概率造成无视部分防御的暴击。 | N6: 在基地中工作时，略微提升石头生产效率。
A7: 4 | B7: Marcus Reed | C7: R | D7: DPS | E7: 突进破甲、单体爆发 | F7: 突进破甲、单体爆发 | G7: 前安保人员，作风强硬，擅长使用动力锤进行中近距离的强力突破。 | H7: 他们的防御，不堪一击！ | I7: 碎颅猛击 | J7: 乘胜追击 | K7: 极地生存 | L7: 冲向生命值最高的敌方目标，对其造成高额伤害并大幅降低其护甲，持续5秒。 | M7: 对生命值低于30%的敌人造成的伤害提升25%。 | N7: 在副玩法中，载具血量提升5%。
A8: 5 | B8: Old Jack | C8: R | D8: TANK | E8: 可靠老兵 | F8: 稳定减伤、新手之友 | G8: 一位经验丰富的老兵，虽然身体因年迈不再巅峰，但他的经验和坚定的意志让他依然是最值得信赖的前排。 | H8: 孩子，待在我身后。这面盾牌和我一样可靠。 | I8: 举盾防御 | J8: 战地经验 | K8: 鼓舞 | L8: 为自身施加一个持续4秒的护盾，吸收少量伤害 | M8: 永久提升自身一定比例的防御力。 | N8: 略微提升周围友军的攻击速度。

Sheet 标准人
A1: Level | B1: Atk | C1: Def | D1: Hp | E1: Crit | F1: CritDamage | G1: Speed | J1: 类别 | K1: Atk | L1: Def | M1: Hp | P1: 人物 | Q1: Atk | R1: Def | S1: Hp
A2: 1 | B2: =100+(A2-1)*40 -> 100 | C2: =500+(A2-1)*50 -> 500 | D2: =2000+(A2-1)*200 -> 2000 | E2: 0.4 | F2: 2 | G2: 1 | J2: R级肉盾 | K2: 0.45364892 | L2: 0.70935961 | M2: 1.0423767 | P2: Old Jack | Q2: 0.45364892 | R2: 0.70935961 | S2: 1.0423767
A3: 2 | B3: =100+(A3-1)*40 -> 140 | C3: =500+(A3-1)*11.02 -> 511.02 | D3: =2000+(A3-1)*200 -> 2200 | E3: 0.4 | F3: 2 | G3: 1 | J3: R级战士 | K3: 0.58974359 | L3: 0.70935961 | M3: 0.67754487 | P3: Marcus Reed | Q3: 0.58974359 | R3: 0.70935961 | S3: 0.67754487
A4: 3 | B4: =100+(A4-1)*40 -> 180 | C4: =500+(A4-1)*11.02 -> 522.04 | D4: =2000+(A4-1)*200 -> 2400 | E4: 0.4 | F4: 2 | G4: 1 | J4: R级远程 | K4: 0.58145957 | L4: 0.94679803 | M4: 0.61828985 | P4: Lena Volt | Q4: 1.2 | R4: 1.2 | S4: 0.74
A5: 4 | B5: =100+(A5-1)*40 -> 220 | C5: =500+(A5-1)*11.02 -> 533.06 | D5: =2000+(A5-1)*200 -> 2600 | E5: 0.4 | F5: 2 | G5: 1 | J5: SR级肉盾 | K5: 0.60552268 | L5: 1.0189655 | M5: 1.52187 | P5: Anvil | Q5: 0.75739645 | R5: 1.3285714 | S5: 2.0013633
A6: 5 | B6: =100+(A6-1)*40 -> 260 | C6: =500+(A6-1)*11.02 -> 544.08 | D6: =2000+(A6-1)*200 -> 2800 | E6: 0.4 | F6: 2 | G6: 1 | J6: SR级战士 | K6: 0.93885602 | L6: 1.0501232 | M6: 1.0545408 | P6: Isabella Frost | Q6: 1.8185404 | R6: 1.453202 | S6: 0.86171015
A7: 6 | B7: =100+(A7-1)*40 -> 300 | C7: =500+(A7-1)*11.02 -> 555.1 | D7: =2000+(A7-1)*200 -> 3000 | E7: 0.4 | F7: 2 | G7: 1 | J7: SR级远程 | K7: 1.2 | L7: 1.2 | M7: 0.74
A8: 7 | B8: =100+(A8-1)*40 -> 340 | C8: =500+(A8-1)*11.02 -> 566.12 | D8: =2000+(A8-1)*200 -> 3200 | E8: 0.4 | F8: 2 | G8: 1 | J8: SSR级肉盾 | K8: 0.75739645 | L8: 1.3285714 | M8: 2.0013633
A9: 8 | B9: =100+(A9-1)*40 -> 380 | C9: =500+(A9-1)*11.02 -> 577.14 | D9: =2000+(A9-1)*200 -> 3400 | E9: 0.4 | F9: 2 | G9: 1 | J9: SSR级战士 | K9: 1.2879684 | L9: 1.3908867 | M9: 1.4315367
A10: 9 | B10: =100+(A10-1)*40 -> 420 | C10: =500+(A10-1)*11.02 -> 588.16 | D10: =2000+(A10-1)*200 -> 3600 | E10: 0.4 | F10: 2 | G10: 1 | J10: SSR级远程 | K10: 1.8185404 | L10: 1.453202 | M10: 0.86171015
A11: 10 | B11: =100+(A11-1)*40 -> 460 | C11: =500+(A11-1)*11.02 -> 599.18 | D11: =2000+(A11-1)*200 -> 3800 | E11: 0.4 | F11: 2 | G11: 1
A12: 11 | B12: =100+(A12-1)*40 -> 500 | C12: =500+(A12-1)*11.02 -> 610.2 | D12: =2000+(A12-1)*200 -> 4000 | E12: 0.4 | F12: 2 | G12: 1
A13: 12 | B13: =100+(A13-1)*40 -> 540 | C13: =500+(A13-1)*11.02 -> 621.22 | D13: =2000+(A13-1)*200 -> 4200 | E13: 0.4 | F13: 2 | G13: 1
A14: 13 | B14: =100+(A14-1)*40 -> 580 | C14: =500+(A14-1)*11.02 -> 632.24 | D14: =2000+(A14-1)*200 -> 4400 | E14: 0.4 | F14: 2 | G14: 1
A15: 14 | B15: =100+(A15-1)*40 -> 620 | C15: =500+(A15-1)*11.02 -> 643.26 | D15: =2000+(A15-1)*200 -> 4600 | E15: 0.4 | F15: 2 | G15: 1
A16: 15 | B16: =100+(A16-1)*40 -> 660 | C16: =500+(A16-1)*11.02 -> 654.28 | D16: =2000+(A16-1)*200 -> 4800 | E16: 0.4 | F16: 2 | G16: 1
A17: 16 | B17: =100+(A17-1)*40 -> 700 | C17: =500+(A17-1)*11.02 -> 665.3 | D17: =2000+(A17-1)*200 -> 5000 | E17: 0.4 | F17: 2 | G17: 1
A18: 17 | B18: =100+(A18-1)*40 -> 740 | C18: =500+(A18-1)*11.02 -> 676.32 | D18: =2000+(A18-1)*200 -> 5200 | E18: 0.4 | F18: 2 | G18: 1
A19: 18 | B19: =100+(A19-1)*40 -> 780 | C19: =500+(A19-1)*11.02 -> 687.34 | D19: =2000+(A19-1)*200 -> 5400 | E19: 0.4 | F19: 2 | G19: 1
A20: 19 | B20: =100+(A20-1)*40 -> 820 | C20: =500+(A20-1)*11.02 -> 698.36 | D20: =2000+(A20-1)*200 -> 5600 | E20: 0.4 | F20: 2 | G20: 1
A21: 20 | B21: =100+(A21-1)*40 -> 860 | C21: =500+(A21-1)*11.02 -> 709.38 | D21: =2000+(A21-1)*200 -> 5800 | E21: 0.4 | F21: 2 | G21: 1
A22: 21 | B22: =100+(A22-1)*40 -> 900 | C22: =500+(A22-1)*11.02 -> 720.4 | D22: =2000+(A22-1)*200 -> 6000 | E22: 0.4 | F22: 2 | G22: 1
... A81: 80 | B81: =100+(A81-1)*40 -> 3260 | C81: =500+(A81-1)*11.02 -> 1370.58 | D81: =2000+(A81-1)*200 -> 17800 | E81: 0.4 | F81: 2 | G81: 1

Sheet 职业测评
A1: 能力 职业 | B1: 生命值 | C1: 攻击力 | D1: 防御力 | E1: 综合能力 | F1: 评级 | G1: 分数
A2: 战士 | B2: B | C2: B | D2: B | E2: =VLOOKUP(B2,$F$1:$G$4,2)+VLOOKUP(C2,$F$1:$G$4,2)+VLOOKUP(D2,$F$1:$G$4,2) -> 330 | F2: A | G2: 120
A3: 远程 | B3: C | C3: A | D3: B | E3: =VLOOKUP(B3,$F$1:$G$4,2)+VLOOKUP(C3,$F$1:$G$4,2)+VLOOKUP(D3,$F$1:$G$4,2) -> 330 | F3: B | G3: 110
A4: 肉盾 | B4: A | C4: C | D4: B | E4: =VLOOKUP(B4,$F$1:$G$4,2)+VLOOKUP(C4,$F$1:$G$4,2)+VLOOKUP(D4,$F$1:$G$4,2) -> 330 | F4: C | G4: 100

Sheet 伤害测试
A1: 等级 | B1: HP | C1: ATK | D1: CRIT% | E1: CRIT_DMG | F1: SPD | G1: 对方DEF | H1: DPS | I1: Finall_DPS | J1: TTK | K1: 防御参数1 | L1: 我方英雄 | M1: 对方英雄 | P1: 同品质同级别 | Q1: SNIP | R1: TANK | S1: DPS | T1: 品质降低，时间减半
A2: 1 | B2: {=_xlfn._xlws.FILTER(英雄数值!H:H,英雄数值!A:A=$M$2)} -> 4000 | C2: {=_xlfn._xlws.FILTER(英雄数值!F:F,英雄数值!A:A=$L$2)} -> 180 | D2: {=_xlfn._xlws.FILTER(英雄数值!I:K,英雄数值!A:A=$L$2)} -> 0.4 | E2: 2 | F2: 1 | G2: {=_xlfn._xlws.FILTER(英雄数值!G:G,英雄数值!A:A=$M$2)} -> 665 | H2: =2*C2*((1+D2*(E2-1)))*(1-(G2/(G2+A2*$K$2+$K$4))) -> 277.54054 | I2: =IF(AND($L$4="SNIP",$M$4="TANK"),H2*1.2,IF(AND($L$4="DPS",$M$4="SNIP"),H2*1.2,IF(AND($L$4="TANK",$M$4="DPS"),H2*1.2,H2))) -> 333.04865 | J2: =B2/I2 -> 12.010257 | K2: 15 | L2: 1 | M2: 2 | P2: SNIP | Q2: 10 | R2: 15 | S2: 12
A3: 2 | B3: 4400 | C3: 252 | D3: 0.4 | E3: 2 | F3: 1 | G3: 679.6566 | H3: =2*C3*((1+D3*(E3-1)))*(1-(G3/(G3+A3*$K$2+$K$4))) -> 387.93458 | I3: =IF(AND($L$4="SNIP",$M$4="TANK"),H3*1.2,IF(AND($L$4="DPS",$M$4="SNIP"),H3*1.2,H3)) -> 465.5215 | J3: =B3/I3 -> 9.4517655 | K3: 防御参数2 | L3: =VLOOKUP(L2,英雄图鉴!A:N,2,TRUE) -> Isabella Frost | M3: =VLOOKUP(M2,英雄图鉴!A:N,2,TRUE) -> Anvil | P3: TANK | Q3: 16 | R3: 30 | S3: 20
A4: 3 | B4: 4800 | C4: 324 | D4: 0.4 | E4: 2 | F4: 1 | G4: 694.3132 | H4: =2*C4*((1+D4*(E4-1)))*(1-(G4/(G4+A4*$K$2+$K$4))) -> 498.00391 | I4: =IF(AND($L$4="SNIP",$M$4="TANK"),H4*1.2,IF(AND($L$4="DPS",$M$4="SNIP"),H4*1.2,H4)) -> 597.6047 | J4: =B4/I4 -> 8.0320654 | K4: 800 | L4: =VLOOKUP(L2,英雄图鉴!A1:D8,4) -> SNIP | M4: =VLOOKUP(M2,英雄图鉴!A1:D8,4) -> TANK | P4: DPS | Q4: 10 | R4: 20 | S4: 15
A5: 4 | B5: 5200 | C5: 396 | D5: 0.4 | E5: 2 | F5: 1 | G5: 708.9698 | H5: =2*C5*((1+D5*(E5-1)))*(1-(G5/(G5+A5*$K$2+$K$4))) -> 607.76696 | I5: =IF(AND($L$4="SNIP",$M$4="TANK"),H5*1.2,IF(AND($L$4="DPS",$M$4="SNIP"),H5*1.2,H5)) -> 729.32035 | J5: =B5/I5 -> 7.1299259
A6: 5 | B6: 5600 | C6: 468 | D6: 0.4 | E6: 2 | F6: 1 | G6: 723.6264 | H6: =2*C6*((1+D6*(E6-1)))*(1-(G6/(G6+A6*$K$2+$K$4))) -> 717.24075 | I6: =IF(AND($L$4="SNIP",$M$4="TANK"),H6*1.2,IF(AND($L$4="DPS",$M$4="SNIP"),H6*1.2,H6)) -> 860.6889 | J6: =B6/I6 -> 6.506416
A7: 6 | B7: 6000 | C7: 540 | D7: 0.4 | E7: 2 | F7: 1 | G7: 738.283 | H7: =2*C7*((1+D7*(E7-1)))*(1-(G7/(G7+A7*$K$2+$K$4))) -> 826.4411 | I7: =IF(AND($L$4="SNIP",$M$4="TANK"),H7*1.2,IF(AND($L$4="DPS",$M$4="SNIP"),H7*1.2,H7)) -> 991.72932 | J7: =B7/I7 -> 6.0500379
A8: 7 | B8: 6400 | C8: 612 | D8: 0.4 | E8: 2 | F8: 1 | G8: 752.9396 | H8: =2*C8*((1+D8*(E8-1)))*(1-(G8/(G8+A8*$K$2+$K$4))) -> 935.38269 | I8: =IF(AND($L$4="SNIP",$M$4="TANK"),H8*1.2,IF(AND($L$4="DPS",$M$4="SNIP"),H8*1.2,H8)) -> 1122.4592 | J8: =B8/I8 -> 5.7017661
A9: 8 | B9: 6800 | C9: 684 | D9: 0.4 | E9: 2 | F9: 1 | G9: 767.5962 | H9: =2*C9*((1+D9*(E9-1)))*(1-(G9/(G9+A9*$K$2+$K$4))) -> 1044.0791 | I9: =IF(AND($L$4="SNIP",$M$4="TANK"),H9*1.2,IF(AND($L$4="DPS",$M$4="SNIP"),H9*1.2,H9)) -> 1252.895 | J9: =B9/I9 -> 5.4274302
A10: 9 | B10: 7200 | C10: 756 | D10: 0.4 | E10: 2 | F10: 1 | G10: 782.2528 | H10: =2*C10*((1+D10*(E10-1)))*(1-(G10/(G10+A10*$K$2+$K$4))) -> 1152.5432 | I10: =IF(AND($L$4="SNIP",$M$4="TANK"),H10*1.2,IF(AND($L$4="DPS",$M$4="SNIP"),H10*1.2,H10)) -> 1383.0518 | J10: =B10/I10 -> 5.2058787
A11: 10 | B11: 7600 | C11: 828 | D11: 0.4 | E11: 2 | F11: 1 | G11: 796.9094 | H11: =2*C11*((1+D11*(E11-1)))*(1-(G11/(G11+A11*$K$2+$K$4))) -> 1260.7866 | I11: =IF(AND($L$4="SNIP",$M$4="TANK"),H11*1.2,IF(AND($L$4="DPS",$M$4="SNIP"),H11*1.2,H11)) -> 1512.9439 | J11: =B11/I11 -> 5.023319
A12: 11 | B12: 8000 | C12: 900 | D12: 0.4 | E12: 2 | F12: 1 | G12: 811.566 | H12: =2*C12*((1+D12*(E12-1)))*(1-(G12/(G12+A12*$K$2+$K$4))) -> 1368.8205 | I12: =IF(AND($L$4="SNIP",$M$4="TANK"),H12*1.2,IF(AND($L$4="DPS",$M$4="SNIP"),H12*1.2,H12)) -> 1642.5846 | J12: =B12/I12 -> 4.8703731
A13: 12 | B13: 8400 | C13: 972 | D13: 0.4 | E13: 2 | F13: 1 | G13: 826.2226 | H13: =2*C13*((1+D13*(E13-1)))*(1-(G13/(G13+A13*$K$2+$K$4))) -> 1476.6552 | I13: =IF(AND($L$4="SNIP",$M$4="TANK"),H13*1.2,IF(AND($L$4="DPS",$M$4="SNIP"),H13*1.2,H13)) -> 1771.9862 | J13: =B13/I13 -> 4.7404431
A14: 13 | B14: 8800 | C14: 1044 | D14: 0.4 | E14: 2 | F14: 1 | G14: 840.8792 | H14: =2*C14*((1+D14*(E14-1)))*(1-(G14/(G14+A14*$K$2+$K$4))) -> 1584.3003 | I14: =IF(AND($L$4="SNIP",$M$4="TANK"),H14*1.2,IF(AND($L$4="DPS",$M$4="SNIP"),H14*1.2,H14)) -> 1901.1604 | J14: =B14/I14 -> 4.628752
A15: 14 | B15: 9200 | C15: 1116 | D15: 0.4 | E15: 2 | F15: 1 | G15: 855.5358 | H15: =2*C15*((1+D15*(E15-1)))*(1-(G15/(G15+A15*$K$2+$K$4))) -> 1691.7649 | I15: =IF(AND($L$4="SNIP",$M$4="TANK"),H15*1.2,IF(AND($L$4="DPS",$M$4="SNIP"),H15*1.2,H15)) -> 2030.1179 | J15: =B15/I15 -> 4.5317565
A16: 15 | B16: 9600 | C16: 1188 | D16: 0.4 | E16: 2 | F16: 1 | G16: 870.1924 | H16: =2*C16*((1+D16*(E16-1)))*(1-(G16/(G16+A16*$K$2+$K$4))) -> 1799.0574 | I16: =IF(AND($L$4="SNIP",$M$4="TANK"),H16*1.2,IF(AND($L$4="DPS",$M$4="SNIP"),H16*1.2,H16)) -> 2158.8689 | J16: =B16/I16 -> 4.446773
... A81: 80 | B81: 35600 | C81: 5868 | D81: 0.4 | E81: 2 | F81: 1 | G81: 1822.8714 | H81: =2*C81*((1+D81*(E81-1)))*(1-(G81/(G81+A81*$K$2+$K$4))) -> 8595.8424 | I81: =IF(AND($L$4="SNIP",$M$4="TANK"),H81*1.2,IF(AND($L$4="DPS",$M$4="SNIP"),H81*1.2,H81)) -> 10315.011 | J81: =B81/I81 -> 3.4512809
